# The code below raise an exception. Why? Modify the code to use a
# try/except block to handle it.

with open('foo.txt') as f:
    data = f.read()
    print(data)

# Why does this code raise an exception? Answer below.
